Workbook

Sheet Input ranges
A1: maximum Demand | B1: 3 | C1: MWh thermal
A2: electrolyser efficiency | B2: 0.5
A3: maximum Electrolyser rated power | B3: =B1/B2 -> 6 | C3: MW electric
A6: Hydrogen tank storage
C7: Volume inside | D7: Max pressure | E7: Temperature | F7: Weight H2 | G7: Source/link
B8: Model 1 | D8: 30 bar
B9: Model 2 | C9: 196 L | D9: 350 bar | F9: 4,7 kg | G9: https://www.hyfindr.com/es/shop/productos/hidrogeno-tipo-4-cilindros-350-bar-196l
B10: Model 3 | C10: 400 L | D10: 700 bar | F10: 16 kg | G10: https://www.hyfindr.com/es/shop/productos/hidrogeno-tipo-4-cilindros-700-bar-400l
B12: operating range 10-90% of pressure?
B16: T [K] | C16: 298.15 | G16: Ideal gas: P[Pa]=n[mol]*R[J/k/mol*T[K]/V[m3]
B17: R | C17: 8.314 | D17: J/K/mol | G17: Real gas (van der Waals equation): P = R*T/(V/n-b)-a/(V/n)^2
B18: a | C18: 0.02476 | D18: m6*Pa/mol2 | H18: h2: a = 0,2476 L^2*bar/mol^2 = 0,02476 m^6*Pa/mol^2
B19: b | C19: 2.661e-05 | D19: m3/mol | H19: h2: b = 0,02661 L/mol = 0,00002661 m^3/mol
C20: 0.002 | D20: kg H2/mol
B22: V [m3] | C22: kg | D22: P [Pa] | E22: P [bar] | G22: V [m3] | H22: kg | I22: P [Pa] | J22: P [bar]
B23: =196/1000 -> 0.196 | C23: 4.7 | D23: =$C$17*$C$16/($B$23/(C23/$C$20)-$C$19)-$C$18/($B$23/(C23/$C$20))^2 -> 40086217 | E23: =D23/100000 -> 400.86217 | G23: =400/1000 -> 0.4 | H23: 16 | I23: =$C$17*$C$16/($G$23/(H23/$C$20)-$C$19)-$C$18/($G$23/(H23/$C$20))^2 -> 96073730 | J23: =I23/100000 -> 960.7373
B24: =196/1000 -> 0.196 | C24: 4.2641163 | D24: =$C$17*$C$16/($B$24/(C24/$C$20)-$C$19)-$C$18/($B$24/(C24/$C$20))^2 -> 35019092 | E24: =D24/100000 -> 350.19092 | G24: =400/1000 -> 0.4 | H24: 13.626343 | I24: =$C$17*$C$16/($G$24/(H24/$C$20)-$C$19)-$C$18/($G$24/(H24/$C$20))^2 -> 70038850 | J24: =I24/100000 -> 700.3885
C25: =C24-0.2 -> 4.0641163 | D25: =$C$17*$C$16/($B$24/(C25/$C$20)-$C$19)-$C$18/($B$24/(C25/$C$20))^2 -> 32829426 | E25: =D25/100000 -> 328.29426 | H25: =H24-0.3 -> 13.326343 | I25: =$C$17*$C$16/($G$24/(H25/$C$20)-$C$19)-$C$18/($G$24/(H25/$C$20))^2 -> 67297890 | J25: =I25/100000 -> 672.9789
C26: =C25-0.2 -> 3.8641163 | D26: =$C$17*$C$16/($B$24/(C26/$C$20)-$C$19)-$C$18/($B$24/(C26/$C$20))^2 -> 30717346 | E26: =D26/100000 -> 307.17346 | H26: =H25-0.3 -> 13.026343 | I26: =$C$17*$C$16/($G$24/(H26/$C$20)-$C$19)-$C$18/($G$24/(H26/$C$20))^2 -> 64657509 | J26: =I26/100000 -> 646.57509
C27: =C26-0.2 -> 3.6641163 | D27: =$C$17*$C$16/($B$24/(C27/$C$20)-$C$19)-$C$18/($B$24/(C27/$C$20))^2 -> 28677946 | E27: =D27/100000 -> 286.77946 | H27: =H26-0.3 -> 12.726343 | I27: =$C$17*$C$16/($G$24/(H27/$C$20)-$C$19)-$C$18/($G$24/(H27/$C$20))^2 -> 62112124 | J27: =I27/100000 -> 621.12124
C28: =C27-0.2 -> 3.4641163 | D28: =$C$17*$C$16/($B$24/(C28/$C$20)-$C$19)-$C$18/($B$24/(C28/$C$20))^2 -> 26706670 | E28: =D28/100000 -> 267.0667 | H28: =H27-0.3 -> 12.426343 | I28: =$C$17*$C$16/($G$24/(H28/$C$20)-$C$19)-$C$18/($G$24/(H28/$C$20))^2 -> 59656534 | J28: =I28/100000 -> 596.56534
C29: =C28-0.2 -> 3.2641163 | D29: =$C$17*$C$16/($B$24/(C29/$C$20)-$C$19)-$C$18/($B$24/(C29/$C$20))^2 -> 24799279 | E29: =D29/100000 -> 247.99279 | H29: =H28-0.3 -> 12.126343 | I29: =$C$17*$C$16/($G$24/(H29/$C$20)-$C$19)-$C$18/($G$24/(H29/$C$20))^2 -> 57285882 | J29: =I29/100000 -> 572.85882
C30: =C29-0.2 -> 3.0641163 | D30: =$C$17*$C$16/($B$24/(C30/$C$20)-$C$19)-$C$18/($B$24/(C30/$C$20))^2 -> 22951825 | E30: =D30/100000 -> 229.51825 | H30: =H29-0.3 -> 11.826343 | I30: =$C$17*$C$16/($G$24/(H30/$C$20)-$C$19)-$C$18/($G$24/(H30/$C$20))^2 -> 54995635 | J30: =I30/100000 -> 549.95635
C31: =C30-0.2 -> 2.8641163 | D31: =$C$17*$C$16/($B$24/(C31/$C$20)-$C$19)-$C$18/($B$24/(C31/$C$20))^2 -> 21160625 | E31: =D31/100000 -> 211.60625 | H31: =H30-0.3 -> 11.526343 | I31: =$C$17*$C$16/($G$24/(H31/$C$20)-$C$19)-$C$18/($G$24/(H31/$C$20))^2 -> 52781549 | J31: =I31/100000 -> 527.81549
C32: =C31-0.2 -> 2.6641163 | D32: =$C$17*$C$16/($B$24/(C32/$C$20)-$C$19)-$C$18/($B$24/(C32/$C$20))^2 -> 19422241 | E32: =D32/100000 -> 194.22241 | H32: =H31-0.3 -> 11.226343 | I32: =$C$17*$C$16/($G$24/(H32/$C$20)-$C$19)-$C$18/($G$24/(H32/$C$20))^2 -> 50639654 | J32: =I32/100000 -> 506.39654
C33: =C32-0.2 -> 2.4641163 | D33: =$C$17*$C$16/($B$24/(C33/$C$20)-$C$19)-$C$18/($B$24/(C33/$C$20))^2 -> 17733460 | E33: =D33/100000 -> 177.3346 | H33: =H32-0.3 -> 10.926343 | I33: =$C$17*$C$16/($G$24/(H33/$C$20)-$C$19)-$C$18/($G$24/(H33/$C$20))^2 -> 48566227 | J33: =I33/100000 -> 485.66227
C34: =C33-0.2 -> 2.2641163 | D34: =$C$17*$C$16/($B$24/(C34/$C$20)-$C$19)-$C$18/($B$24/(C34/$C$20))^2 -> 16091274 | E34: =D34/100000 -> 160.91274 | H34: =H33-0.3 -> 10.626343 | I34: =$C$17*$C$16/($G$24/(H34/$C$20)-$C$19)-$C$18/($G$24/(H34/$C$20))^2 -> 46557776 | J34: =I34/100000 -> 465.57776
C35: =C34-0.2 -> 2.0641163 | D35: =$C$17*$C$16/($B$24/(C35/$C$20)-$C$19)-$C$18/($B$24/(C35/$C$20))^2 -> 14492866 | E35: =D35/100000 -> 144.92866 | H35: =H34-0.3 -> 10.326343 | I35: =$C$17*$C$16/($G$24/(H35/$C$20)-$C$19)-$C$18/($G$24/(H35/$C$20))^2 -> 44611020 | J35: =I35/100000 -> 446.1102
C36: =C35-0.2 -> 1.8641163 | D36: =$C$17*$C$16/($B$24/(C36/$C$20)-$C$19)-$C$18/($B$24/(C36/$C$20))^2 -> 12935593 | E36: =D36/100000 -> 129.35593 | H36: =H35-0.3 -> 10.026343 | I36: =$C$17*$C$16/($G$24/(H36/$C$20)-$C$19)-$C$18/($G$24/(H36/$C$20))^2 -> 42722875 | J36: =I36/100000 -> 427.22875
... C45: =C44-0.2 -> 0.064116308 | D45: =$C$17*$C$16/($B$24/(C45/$C$20)-$C$19)-$C$18/($B$24/(C45/$C$20))^2 -> 406550.59 | E45: =D45/100000 -> 4.0655059 | H45: =H44-0.3 -> 7.3263431 | I45: =$C$17*$C$16/($G$24/(H45/$C$20)-$C$19)-$C$18/($G$24/(H45/$C$20))^2 -> 27938805 | J45: =I45/100000 -> 279.38805
H46: =H45-0.3 -> 7.0263431 | I46: =$C$17*$C$16/($G$24/(H46/$C$20)-$C$19)-$C$18/($G$24/(H46/$C$20))^2 -> 26501452 | J46: =I46/100000 -> 265.01452
H47: =H46-0.3 -> 6.7263431 | I47: =$C$17*$C$16/($G$24/(H47/$C$20)-$C$19)-$C$18/($G$24/(H47/$C$20))^2 -> 25098371 | J47: =I47/100000 -> 250.98371
H48: =H47-0.3 -> 6.4263431 | I48: =$C$17*$C$16/($G$24/(H48/$C$20)-$C$19)-$C$18/($G$24/(H48/$C$20))^2 -> 23727993 | J48: =I48/100000 -> 237.27993
H49: =H48-0.3 -> 6.1263431 | I49: =$C$17*$C$16/($G$24/(H49/$C$20)-$C$19)-$C$18/($G$24/(H49/$C$20))^2 -> 22388826 | J49: =I49/100000 -> 223.88826
H50: =H49-0.3 -> 5.8263431 | I50: =$C$17*$C$16/($G$24/(H50/$C$20)-$C$19)-$C$18/($G$24/(H50/$C$20))^2 -> 21079453 | J50: =I50/100000 -> 210.79453
H51: =H50-0.3 -> 5.5263431 | I51: =$C$17*$C$16/($G$24/(H51/$C$20)-$C$19)-$C$18/($G$24/(H51/$C$20))^2 -> 19798526 | J51: =I51/100000 -> 197.98526
H52: =H51-0.3 -> 5.2263431 | I52: =$C$17*$C$16/($G$24/(H52/$C$20)-$C$19)-$C$18/($G$24/(H52/$C$20))^2 -> 18544761 | J52: =I52/100000 -> 185.44761
H53: =H52-0.3 -> 4.9263431 | I53: =$C$17*$C$16/($G$24/(H53/$C$20)-$C$19)-$C$18/($G$24/(H53/$C$20))^2 -> 17316937 | J53: =I53/100000 -> 173.16937
H54: =H53-0.3 -> 4.6263431 | I54: =$C$17*$C$16/($G$24/(H54/$C$20)-$C$19)-$C$18/($G$24/(H54/$C$20))^2 -> 16113890 | J54: =I54/100000 -> 161.1389
H55: =H54-0.3 -> 4.3263431 | I55: =$C$17*$C$16/($G$24/(H55/$C$20)-$C$19)-$C$18/($G$24/(H55/$C$20))^2 -> 14934509 | J55: =I55/100000 -> 149.34509
...

Sheet UHI analysis
A1: Electrolyser | C1: --> power rate pressure = 30 bar (PEM) | G1: H2 tank (295,15 K; 196 L) | M1: H2 tank (295,15 K; 400 L)
A2: Rated power [kW] | B2: H2 production [ | C2: UHI | G2: Inventary [kg H2] | H2: Pressure [bar] | I2: P g [bar] | J2: UHI | M2: Inventary [kg H2] | N2: Pressure [bar] | O2: P g [bar] | P2: UHI
A3: ='Input ranges'!B3*1000 -> 6000 | C3: 3 | F3: 1 | G3: 4.2641163 | H3: 350.19092 | I3: =H3-1 -> 349.19092 | J3: =Results_Tank1!$M$3 -> 0.030187118 | L3: 1 | M3: 13.626343 | N3: 700.3885 | O3: =N3-1 -> 699.3885 | P3: =Results_Tank2!$M$3 -> 0.065577858
A4: =A3-100 -> 5900 | C4: 3 | F4: 2 | G4: 4.0641163 | H4: 328.29426 | I4: =H4-1 -> 327.29426 | J4: =Results_Tank1!$M$6 -> 0.029985624 | L4: 2 | M4: 13.326343 | N4: 672.9789 | O4: =N4-1 -> 671.9789 | P4: =Results_Tank2!$M$6 -> 0.065153902
A5: =A4-100 -> 5800 | F5: 3 | G5: 3.8641163 | H5: 307.17346 | I5: =H5-1 -> 306.17346 | J5: =Results_Tank1!$M$9 -> 0.029626523 | L5: 3 | M5: 13.026343 | N5: 646.57509 | O5: =N5-1 -> 645.57509 | P5: =Results_Tank2!$M$9 -> 0.064718062
A6: =A5-100 -> 5700 | F6: 4 | G6: 3.6641163 | H6: 286.77946 | I6: =H6-1 -> 285.77946 | J6: =Results_Tank1!$M$12 -> 0.029249193 | L6: 4 | M6: 12.726343 | N6: 621.12124 | O6: =N6-1 -> 620.12124 | P6: =Results_Tank2!$M$12 -> 0.064285474
A7: =A6-100 -> 5600 | F7: 5 | G7: 3.4641163 | H7: 267.0667 | I7: =H7-1 -> 266.0667 | J7: =Results_Tank1!$M$15 -> 0.028467784 | L7: 5 | M7: 12.426343 | N7: 596.56534 | O7: =N7-1 -> 595.56534 | P7: =Results_Tank2!$M$15 -> 0.063820315
A8: =A7-100 -> 5500 | F8: 6 | G8: 3.2641163 | H8: 247.99279 | I8: =H8-1 -> 246.99279 | J8: =Results_Tank1!$M$18 -> 0.027504235 | L8: 6 | M8: 12.126343 | N8: 572.85882 | O8: =N8-1 -> 571.85882 | P8: =Results_Tank2!$M$18 -> 0.063345563
A9: =A8-100 -> 5400 | F9: 7 | G9: 3.0641163 | H9: 229.51825 | I9: =H9-1 -> 228.51825 | J9: =Results_Tank1!$M$21 -> 0.026431327 | L9: 7 | M9: 11.826343 | N9: 549.95635 | O9: =N9-1 -> 548.95635 | P9: =Results_Tank2!$M$21 -> 0.062862344
A10: =A9-100 -> 5300 | F10: 8 | G10: 2.8641163 | H10: 211.60625 | I10: =H10-1 -> 210.60625 | J10: =Results_Tank1!$M$24 -> 0.025183954 | L10: 8 | M10: 11.526343 | N10: 527.81549 | O10: =N10-1 -> 526.81549 | P10: =Results_Tank2!$M$24 -> 0.062371612
A11: =A10-100 -> 5200 | F11: 9 | G11: 2.6641163 | H11: 194.22241 | I11: =H11-1 -> 193.22241 | J11: =Results_Tank1!$M$27 -> 0.017112994 | L11: 9 | M11: 11.226343 | N11: 506.39654 | O11: =N11-1 -> 505.39654 | P11: =Results_Tank2!$M$27 -> 0.061411671
A12: =A11-100 -> 5100 | C12: 3 | F12: 10 | G12: 2.4641163 | H12: 177.3346 | I12: =H12-1 -> 176.3346 | J12: =Results_Tank1!$M$30 -> 0.016868423 | L12: 10 | M12: 10.926343 | N12: 485.66227 | O12: =N12-1 -> 484.66227 | P12: =Results_Tank2!$M$30 -> 0.060094039
A13: =A12-100 -> 5000 | C13: 2 | F13: 11 | G13: 2.2641163 | H13: 160.91274 | I13: =H13-1 -> 159.91274 | J13: =Results_Tank1!$M$33 -> 0.016529319 | L13: 11 | M13: 10.626343 | N13: 465.57776 | O13: =N13-1 -> 464.57776 | P13: =Results_Tank2!$M$33 -> 0.058611732
A14: =A13-100 -> 4900 | F14: 12 | G14: 2.0641163 | H14: 144.92866 | I14: =H14-1 -> 143.92866 | J14: =Results_Tank1!$M$36 -> 0.016150439 | L14: 12 | M14: 10.326343 | N14: 446.1102 | O14: =N14-1 -> 445.1102 | P14: =Results_Tank2!$M$36 -> 0.057102397
A15: =A14-100 -> 4800 | F15: 13 | G15: 1.8641163 | H15: 129.35593 | I15: =H15-1 -> 128.35593 | J15: =Results_Tank1!$M$39 -> 0.015718523 | L15: 13 | M15: 10.026343 | N15: 427.22875 | O15: =N15-1 -> 426.22875 | P15: =Results_Tank2!$M$39 -> 0.055347979
A16: =A15-100 -> 4700 | F16: 14 | G16: 1.6641163 | H16: 114.16974 | I16: =H16-1 -> 113.16974 | J16: =Results_Tank1!$M$42 -> 0.015228878 | L16: 14 | M16: 9.7263431 | N16: 408.90439 | O16: =N16-1 -> 407.90439 | P16: =Results_Tank2!$M$42 -> 0.044804504
A17: =A16-100 -> 4600 | F17: 15 | G17: 1.4641163 | H17: 99.346782 | I17: =H17-1 -> 98.346782 | J17: =Results_Tank1!$M$45 -> 0.013918568 | L17: 15 | M17: 9.4263431 | N17: 391.1098 | O17: =N17-1 -> 390.1098 | P17: =Results_Tank2!$M$45 -> 0.044409251
A18: =A17-100 -> 4500 | F18: 16 | G18: 1.2641163 | H18: 84.865132 | I18: =H18-1 -> 83.865132 | J18: =Results_Tank1!$M$48 -> 0.0084924175 | L18: 16 | M18: 9.1263431 | N18: 373.8192 | O18: =N18-1 -> 372.8192 | P18: =Results_Tank2!$M$48 -> 0.044004454
A19: =A18-100 -> 4400 | F19: 17 | G19: 1.0641163 | H19: 70.704147 | I19: =H19-1 -> 69.704147 | J19: =Results_Tank1!$M$51 -> 0.0073587881 | L19: 17 | M19: 8.8263431 | N19: 357.0083 | O19: =N19-1 -> 356.0083 | P19: =Results_Tank2!$M$51 -> 0.043593238
A20: =A19-100 -> 4300 | F20: 18 | G20: 0.86411631 | H20: 56.844374 | I20: =H20-1 -> 55.844374 | J20: =Results_Tank1!$M$54 -> 0.0068555099 | L20: 18 | M20: 8.5263431 | N20: 340.65412 | O20: =N20-1 -> 339.65412 | P20: =Results_Tank2!$M$54 -> 0.043162174
A21: =A20-100 -> 4200 | F21: 19 | G21: 0.66411631 | H21: 43.267468 | I21: =H21-1 -> 42.267468 | J21: =Results_Tank1!$M$57 -> 0.006398788 | L21: 19 | M21: 8.2263431 | N21: 324.73499 | O21: =N21-1 -> 323.73499 | P21: =Results_Tank2!$M$57 -> 0.042706911
A22: =A21-100 -> 4100 | F22: 20 | G22: 0.46411631 | H22: 29.956112 | I22: =H22-1 -> 28.956112 | J22: =Results_Tank1!$M$60 -> 0.0035558527 | L22: 20 | M22: 7.9263431 | N22: 309.23037 | O22: =N22-1 -> 308.23037 | P22: =Results_Tank2!$M$60 -> 0.042270863
A23: =A22-100 -> 4000 | C23: 1 | F23: 21 | G23: 0.26411631 | H23: 16.893947 | I23: =H23-1 -> 15.893947 | J23: =Results_Tank1!$M$63 -> 0.0020816617 | L23: 21 | M23: 7.6263431 | N23: 294.12086 | O23: =N23-1 -> 293.12086 | P23: =Results_Tank2!$M$63 -> 0.041830627
A24: =A23-100 -> 3900 | C24: 1 | F24: 22 | G24: 0.064116308 | H24: 4.0655059 | I24: =H24-1 -> 3.0655059 | J24: =Results_Tank1!$M$66 -> 0 | L24: 22 | M24: 7.3263431 | N24: 279.38805 | O24: =N24-1 -> 278.38805 | P24: =Results_Tank2!$M$66 -> 0.041383334
A25: =A24-100 -> 3800 | C25: 1 | L25: 23 | M25: 7.0263431 | N25: 265.01452 | O25: =N25-1 -> 264.01452 | P25: =Results_Tank2!$M$69 -> 0.040654397
A26: =A25-100 -> 3700 | C26: 1 | L26: 24 | M26: 6.7263431 | N26: 250.98371 | O26: =N26-1 -> 249.98371 | P26: =Results_Tank2!$M$72 -> 0.038640901
A27: =A26-100 -> 3600 | C27: 1 | L27: 25 | M27: 6.4263431 | N27: 237.27993 | O27: =N27-1 -> 236.27993 | P27: =Results_Tank2!$M$75 -> 0.036013347
A28: =A27-100 -> 3500 | C28: 1 | L28: 26 | M28: 6.1263431 | N28: 223.88826 | O28: =N28-1 -> 222.88826 | P28: =Results_Tank2!$M$78 -> 0.027923917
A29: =A28-100 -> 3400 | L29: 27 | M29: 5.8263431 | N29: 210.79453 | O29: =N29-1 -> 209.79453 | P29: =Results_Tank2!$M$81 -> 0.027529563
A30: =A29-100 -> 3300 | E30: thermal load fixed and cover the thermal load with full H2 with an efficiency of 50% | L30: 28 | M30: 5.5263431 | N30: 197.98526 | O30: =N30-1 -> 196.98526 | P30: =Results_Tank2!$M$84 -> 0.027117559
A31: =A30-100 -> 3200 | L31: 29 | M31: 5.2263431 | N31: 185.44761 | O31: =N31-1 -> 184.44761 | P31: =Results_Tank2!$M$87 -> 0.026691205
A32: =A31-100 -> 3100 | L32: 30 | M32: 4.9263431 | N32: 173.16937 | O32: =N32-1 -> 172.16937 | P32: =Results_Tank2!$M$90 -> 0.026241698
A33: =A32-100 -> 3000 | C33: 0.5 | L33: 31 | M33: 4.6263431 | N33: 161.1389 | O33: =N33-1 -> 160.1389 | P33: =Results_Tank2!$M$93 -> 0.025807259
A34: =A33-100 -> 2900 | L34: 32 | M34: 4.3263431 | N34: 149.34509 | O34: =N34-1 -> 148.34509 | P34: =Results_Tank2!$M$96 -> 0.025371124
A35: =A34-100 -> 2800 | L35: 33 | M35: 4.0263431 | N35: 137.77736 | O35: =N35-1 -> 136.77736 | P35: =Results_Tank2!$M$99 -> 0.02426113
A36: =A35-100 -> 2700 | L36: 34 | M36: 3.7263431 | N36: 126.42561 | O36: =N36-1 -> 125.42561 | P36: =Results_Tank2!$M$102 -> 0.015644362
A37: =A36-100 -> 2600 | L37: 35 | M37: 3.4263431 | N37: 115.28018 | O37: =N37-1 -> 114.28018 | P37: =Results_Tank2!$M$105 -> 0.01528159
A38: =A37-100 -> 2500 | L38: 36 | M38: 3.1263431 | N38: 104.33185 | O38: =N38-1 -> 103.33185 | P38: =Results_Tank2!$M$108 -> 0.014897389
A39: =A38-100 -> 2400 | L39: 37 | M39: 2.8263431 | N39: 93.571811 | O39: =N39-1 -> 92.571811 | P39: =Results_Tank2!$M$111 -> 0.014493488
A40: =A39-100 -> 2300 | L40: 38 | M40: 2.5263431 | N40: 82.991634 | O40: =N40-1 -> 81.991634 | P40: =Results_Tank2!$M$114 -> 0.014085269
...

Sheet Credit factor
A1: Reference Component | B1: Label | C1: LOC | D1: LOC description | E1: Frequency [event/year] | F1: TNO Purple Book
A2: Pressure vessel (storage) | B2: Tank | C2: 1 | D2: Catastrophic failure | E2: 5e-07
C3: 2 | D3: 10 mm leak | E3: 1e-05
C4: 3 | D4: Continuous 10 min | E4: 5e-07
A6: Thresholds
A7: Flashfire | C7: 1/2 LFL
A8: Jet Fire | C8: 7 | D8: kW/m2
A9: Pool Fire | C9: 7 | D9: kW/m2 | E9: *not relevant for us
A10: Fireball | C10: 7 | D10: kW/m2
A11: VCE | C11: 0.14 | D11: bar

Sheet Results_Tank1
C1: Storage tank | E1: Credit factor | G1: Consequences (distances) | M1: IS-KPI
A2: label | B2: mass [kg] | C2: P (bar) | D2: Scenario | E2: Cf [event/yr] | G2: d FLASH FIRE [m] | H2: d JET FIRE [m] | I2: d FIREBALL [m] | J2: d VCE [m] | K2: general d [m] | L2: UHIj | M2: UHI [m2/yr] - Unit inherent Hazard Index
A3: 1 | B3: ='UHI analysis'!G3 -> 4.2641163 | C3: ='UHI analysis'!H3 -> 350.19092 | D3: ='Credit factor'!$D$2 -> Catastrophic failure | E3: ='Credit factor'!$E$2 -> 5e-07 | G3: 7.22012 | I3: 31.8428 | K3: =MAX(G3:J3) -> 31.8428 | L3: =+K3^2*E3 -> 0.00050698196 | M3: =+SUM(L3:L5) -> 0.030187118
D4: ='Credit factor'!$D$3 -> 10 mm leak | E4: ='Credit factor'!$E$3 -> 1e-05 | G4: 46.5664 | H4: 28.899 | I4: 31.8428 | J4: 54.4693 | K4: =MAX(G4:J4) -> 54.4693 | L4: =+K4^2*E4 -> 0.029669046
D5: ='Credit factor'!$D$4 -> Continuous 10 min | E5: ='Credit factor'!$E$4 -> 5e-07 | G5: 4.70943 | H5: 2.21353 | K5: =MAX(G5:J5) -> 4.70943 | L5: =+K5^2*E5 -> 1.1089365e-05
A6: 2 | B6: 4.0641163 | C6: 328.29426 | D6: ='Credit factor'!$D$2 -> Catastrophic failure | E6: ='Credit factor'!$E$2 -> 5e-07 | G6: 7.09909 | I6: 31.3568 | K6: =MAX(G6:J6) -> 31.3568 | L6: =+K6^2*E6 -> 0.00049162445 | M6: =+SUM(L6:L8) -> 0.029985624
D7: ='Credit factor'!$D$3 -> 10 mm leak | E7: ='Credit factor'!$E$3 -> 1e-05 | G7: 45.683 | H7: 28.1702 | I7: 31.3568 | J7: 54.2986 | K7: =MAX(G7:J7) -> 54.2986 | L7: =+K7^2*E7 -> 0.02948338
D8: ='Credit factor'!$D$4 -> Continuous 10 min | E8: ='Credit factor'!$E$4 -> 5e-07 | G8: 4.60864 | H8: 2.16863 | K8: =MAX(G8:J8) -> 4.60864 | L8: =+K8^2*E8 -> 1.0619781e-05
A9: 3 | B9: 3.8641163 | C9: 307.17346 | D9: ='Credit factor'!$D$2 -> Catastrophic failure | E9: ='Credit factor'!$E$2 -> 5e-07 | G9: 6.9742 | I9: 30.8657 | K9: =MAX(G9:J9) -> 30.8657 | L9: =+K9^2*E9 -> 0.00047634572 | M9: =+SUM(L9:L11) -> 0.029626523
D10: ='Credit factor'!$D$3 -> 10 mm leak | E10: ='Credit factor'!$E$3 -> 1e-05 | G10: 44.7639 | H10: 27.4347 | I10: 30.8657 | J10: 53.9815 | K10: =MAX(G10:J10) -> 53.9815 | L10: =+K10^2*E10 -> 0.029140023
D11: ='Credit factor'!$D$4 -> Continuous 10 min | E11: ='Credit factor'!$E$4 -> 5e-07 | G11: 4.50635 | H11: 2.1222 | K11: =MAX(G11:J11) -> 4.50635 | L11: =+K11^2*E11 -> 1.0153595e-05
A12: 4 | B12: 3.6641163 | C12: 286.77946 | D12: ='Credit factor'!$D$2 -> Catastrophic failure | E12: ='Credit factor'!$E$2 -> 5e-07 | G12: 6.84492 | I12: 30.3439 | K12: =MAX(G12:J12) -> 30.3439 | L12: =+K12^2*E12 -> 0.00046037613 | M12: =+SUM(L12:L14) -> 0.029249193
D13: ='Credit factor'!$D$3 -> 10 mm leak | E13: ='Credit factor'!$E$3 -> 1e-05 | G13: 43.8333 | H13: 26.6908 | I13: 30.3439 | J13: 53.6462 | K13: =MAX(G13:J13) -> 53.6462 | L13: =+K13^2*E13 -> 0.028779148
D14: ='Credit factor'!$D$4 -> Continuous 10 min | E14: ='Credit factor'!$E$4 -> 5e-07 | G14: 4.39751 | H14: 2.07413 | K14: =MAX(G14:J14) -> 4.39751 | L14: =+K14^2*E14 -> 9.6690471e-06
A15: 5 | B15: 3.4641163 | C15: 267.0667 | D15: ='Credit factor'!$D$2 -> Catastrophic failure | E15: ='Credit factor'!$E$2 -> 5e-07 | G15: 6.70962 | I15: 29.7963 | K15: =MAX(G15:J15) -> 29.7963 | L15: =+K15^2*E15 -> 0.00044390975 | M15: =+SUM(L15:L17) -> 0.028467784
D16: ='Credit factor'!$D$3 -> 10 mm leak | E16: ='Credit factor'!$E$3 -> 1e-05 | G16: 42.8893 | H16: 25.9368 | I16: 29.7963 | J16: 52.9289 | K16: =MAX(G16:J16) -> 52.9289 | L16: =+K16^2*E16 -> 0.028014685
D17: ='Credit factor'!$D$4 -> Continuous 10 min | E17: ='Credit factor'!$E$4 -> 5e-07 | G17: 4.28723 | H17: 2.02431 | K17: =MAX(G17:J17) -> 4.28723 | L17: =+K17^2*E17 -> 9.1901705e-06
A18: 6 | B18: 3.2641163 | C18: 247.99279 | D18: ='Credit factor'!$D$2 -> Catastrophic failure | E18: ='Credit factor'!$E$2 -> 5e-07 | G18: 6.56937 | I18: 29.2416 | K18: =MAX(G18:J18) -> 29.2416 | L18: =+K18^2*E18 -> 0.00042753559 | M18: =+SUM(L18:L20) -> 0.027504235
D19: ='Credit factor'!$D$3 -> 10 mm leak | E19: ='Credit factor'!$E$3 -> 1e-05 | G19: 41.8835 | H19: 25.1755 | I19: 29.2422 | J19: 52.0269 | K19: =MAX(G19:J19) -> 52.0269 | L19: =+K19^2*E19 -> 0.027067983
D20: ='Credit factor'!$D$4 -> Continuous 10 min | E20: ='Credit factor'!$E$4 -> 5e-07 | G20: 4.17532 | H20: 1.9726 | K20: =MAX(G20:J20) -> 4.17532 | L20: =+K20^2*E20 -> 8.7166486e-06
A21: 7 | B21: 3.0641163 | C21: 229.51825 | D21: ='Credit factor'!$D$2 -> Catastrophic failure | E21: ='Credit factor'!$E$2 -> 5e-07 | G21: 6.42348 | I21: 28.6476 | K21: =MAX(G21:J21) -> 28.6476 | L21: =+K21^2*E21 -> 0.00041034249 | M21: =+SUM(L21:L23) -> 0.026431327
D22: ='Credit factor'!$D$3 -> 10 mm leak | E22: ='Credit factor'!$E$3 -> 1e-05 | G22: 40.8572 | H22: 24.3893 | I22: 28.6476 | J22: 51.0027 | K22: =MAX(G22:J22) -> 51.0027 | L22: =+K22^2*E22 -> 0.026012754
D23: ='Credit factor'!$D$4 -> Continuous 10 min | E23: ='Credit factor'!$E$4 -> 5e-07 | G23: 4.0573 | H23: 1.91884 | K23: =MAX(G23:J23) -> 4.0573 | L23: =+K23^2*E23 -> 8.2308416e-06
A24: 8 | B24: 2.8641163 | C24: 211.60625 | D24: ='Credit factor'!$D$2 -> Catastrophic failure | E24: ='Credit factor'!$E$2 -> 5e-07 | G24: 6.26873 | I24: 28.03 | K24: =MAX(G24:J24) -> 28.03 | L24: =+K24^2*E24 -> 0.00039284045 | M24: =+SUM(L24:L26) -> 0.025183954
D25: ='Credit factor'!$D$3 -> 10 mm leak | E25: ='Credit factor'!$E$3 -> 1e-05 | G25: 39.7931 | H25: 23.5913 | I25: 28.03 | J25: 49.7829 | K25: =MAX(G25:J25) -> 49.7829 | L25: =+K25^2*E25 -> 0.024783371
D26: ='Credit factor'!$D$4 -> Continuous 10 min | E26: ='Credit factor'!$E$4 -> 5e-07 | G26: 3.93511 | H26: 1.86283 | K26: =MAX(G26:J26) -> 3.93511 | L26: =+K26^2*E26 -> 7.7425454e-06
A27: 9 | B27: 2.6641163 | C27: 194.22241 | D27: ='Credit factor'!$D$2 -> Catastrophic failure | E27: ='Credit factor'!$E$2 -> 5e-07 | G27: 6.10913 | I27: 27.4021 | K27: =MAX(G27:J27) -> 27.4021 | L27: =+K27^2*E27 -> 0.00037543754 | M27: =+SUM(L27:L29) -> 0.017112994
D28: ='Credit factor'!$D$3 -> 10 mm leak | E28: ='Credit factor'!$E$3 -> 1e-05 | G28: 38.6921 | H28: 22.7734 | I28: 27.4021 | J28: 40.9027 | K28: =MAX(G28:J28) -> 40.9027 | L28: =+K28^2*E28 -> 0.016730309
D29: ='Credit factor'!$D$4 -> Continuous 10 min | E29: ='Credit factor'!$E$4 -> 5e-07 | G29: 3.80735 | H29: 1.80435 | K29: =MAX(G29:J29) -> 3.80735 | L29: =+K29^2*E29 -> 7.247957e-06
A30: 10 | B30: 2.4641163 | C30: 177.3346 | D30: ='Credit factor'!$D$2 -> Catastrophic failure | E30: ='Credit factor'!$E$2 -> 5e-07 | G30: 5.94284 | I30: 26.7279 | K30: =MAX(G30:J30) -> 26.7279 | L30: =+K30^2*E30 -> 0.00035719032 | M30: =+SUM(L30:L32) -> 0.016868423
D31: ='Credit factor'!$D$3 -> 10 mm leak | E31: ='Credit factor'!$E$3 -> 1e-05 | G31: 37.5207 | H31: 21.932 | I31: 26.7279 | J31: 40.6257 | K31: =MAX(G31:J31) -> 40.6257 | L31: =+K31^2*E31 -> 0.016504475
D32: ='Credit factor'!$D$4 -> Continuous 10 min | E32: ='Credit factor'!$E$4 -> 5e-07 | G32: 3.67637 | H32: 1.74312 | K32: =MAX(G32:J32) -> 3.67637 | L32: =+K32^2*E32 -> 6.7578482e-06
A33: 11 | B33: 2.2641163 | C33: 160.91274 | D33: ='Credit factor'!$D$2 -> Catastrophic failure | E33: ='Credit factor'!$E$2 -> 5e-07 | G33: 5.76592 | I33: 26.0173 | K33: =MAX(G33:J33) -> 26.0173 | L33: =+K33^2*E33 -> 0.00033844995 | M33: =+SUM(L33:L35) -> 0.016529319
D34: ='Credit factor'!$D$3 -> 10 mm leak | E34: ='Credit factor'!$E$3 -> 1e-05 | G34: 36.3178 | H34: 21.0679 | I34: 26.0173 | J34: 40.2301 | K34: =MAX(G34:J34) -> 40.2301 | L34: =+K34^2*E34 -> 0.016184609
D35: ='Credit factor'!$D$4 -> Continuous 10 min | E35: ='Credit factor'!$E$4 -> 5e-07 | G35: 3.53835 | H35: 1.67881 | K35: =MAX(G35:J35) -> 3.53835 | L35: =+K35^2*E35 -> 6.2599604e-06
A36: 12 | B36: 2.0641163 | C36: 144.92866 | D36: ='Credit factor'!$D$2 -> Catastrophic failure | E36: ='Credit factor'!$E$2 -> 5e-07 | G36: 5.5788 | I36: 25.2432 | K36: =MAX(G36:J36) -> 25.2432 | L36: =+K36^2*E36 -> 0.00031860957 | M36: =+SUM(L36:L38) -> 0.016150439
D37: ='Credit factor'!$D$3 -> 10 mm leak | E37: ='Credit factor'!$E$3 -> 1e-05 | G37: 34.9963 | H37: 20.166 | I37: 25.2432 | J37: 39.782 | K37: =MAX(G37:J37) -> 39.782 | L37: =+K37^2*E37 -> 0.015826075
D38: ='Credit factor'!$D$4 -> Continuous 10 min | E38: ='Credit factor'!$E$4 -> 5e-07 | G38: 3.39235 | H38: 1.60866 | K38: =MAX(G38:J38) -> 3.39235 | L38: =+K38^2*E38 -> 5.7540193e-06
A39: 13 | B39: 1.8641163 | C39: 129.35593 | D39: ='Credit factor'!$D$2 -> Catastrophic failure | E39: ='Credit factor'!$E$2 -> 5e-07 | G39: 5.37748 | I39: 24.4418 | K39: =MAX(G39:J39) -> 24.4418 | L39: =+K39^2*E39 -> 0.00029870079 | M39: =+SUM(L39:L41) -> 0.015718523
D40: ='Credit factor'!$D$3 -> 10 mm leak | E40: ='Credit factor'!$E$3 -> 1e-05 | G40: 33.608 | H40: 19.2249 | I40: 24.4418 | J40: 39.2614 | K40: =MAX(G40:J40) -> 39.2614 | L40: =+K40^2*E40 -> 0.015414575
...

Sheet Results_Tank2
C1: Storage tank | E1: Credit factor | G1: Consequences (distances) | M1: IS-KPI
A2: label | B2: m (kg) | C2: P (bar) | D2: Scenario | E2: Cf [event/yr] | G2: d FLASH FIRE [m] | H2: d JET FIRE [m] | I2: d FIREBALL [m] | J2: d VCE [m] | K2: general d [m] | L2: UHIj | M2: UHI [m2/yr] - Unit inherent Hazard Index
A3: 1 | B3: 13.626343 | C3: 700.3885 | D3: ='Credit factor'!$D$2 -> Catastrophic failure | E3: ='Credit factor'!$E$2 -> 5e-07 | G3: 10.9027 | I3: 46.1351 | J3: 31.509 | K3: =MAX(G3:J3) -> 46.1351 | L3: =+K3^2*E3 -> 0.0010642237 | M3: =+SUM(L3:L5) -> 0.065577858
D4: ='Credit factor'!$D$3 -> 10 mm leak | E4: ='Credit factor'!$E$3 -> 1e-05 | G4: 65.0345 | H4: 37.6062 | I4: 46.1351 | J4: 80.2995 | K4: =MAX(G4:J4) -> 80.2995 | L4: =+K4^2*E4 -> 0.064480097
D5: ='Credit factor'!$D$4 -> Continuous 10 min | E5: ='Credit factor'!$E$4 -> 5e-07 | G5: 8.18988 | H5: 3.75843 | K5: =MAX(G5:J5) -> 8.18988 | L5: =+K5^2*E5 -> 3.3537067e-05
A6: 2 | B6: 13.326343 | C6: 672.9789 | D6: ='Credit factor'!$D$2 -> Catastrophic failure | E6: ='Credit factor'!$E$2 -> 5e-07 | G6: 10.8207 | I6: 45.8038 | J6: 31.1016 | K6: =MAX(G6:J6) -> 45.8038 | L6: =+K6^2*E6 -> 0.001048994 | M6: =+SUM(L6:L8) -> 0.065153902
D7: ='Credit factor'!$D$3 -> 10 mm leak | E7: ='Credit factor'!$E$3 -> 1e-05 | G7: 64.3081 | H7: 37.0626 | I7: 45.8053 | J7: 80.045 | K7: =MAX(G7:J7) -> 80.045 | L7: =+K7^2*E7 -> 0.06407202
D8: ='Credit factor'!$D$4 -> Continuous 10 min | E8: ='Credit factor'!$E$4 -> 5e-07 | G8: 8.11022 | H8: 3.72603 | K8: =MAX(G8:J8) -> 8.11022 | L8: =+K8^2*E8 -> 3.2887834e-05
A9: 3 | B9: 13.026343 | C9: 646.57509 | D9: ='Credit factor'!$D$2 -> Catastrophic failure | E9: ='Credit factor'!$E$2 -> 5e-07 | G9: 10.7378 | I9: 45.4513 | J9: 30.6947 | K9: =MAX(G9:J9) -> 45.4513 | L9: =+K9^2*E9 -> 0.0010329103 | M9: =+SUM(L9:L11) -> 0.064718062
D10: ='Credit factor'!$D$3 -> 10 mm leak | E10: ='Credit factor'!$E$3 -> 1e-05 | G10: 63.5816 | H10: 36.5225 | I10: 45.4513 | J10: 79.7828 | K10: =MAX(G10:J10) -> 79.7828 | L10: =+K10^2*E10 -> 0.063652952
D11: ='Credit factor'!$D$4 -> Continuous 10 min | E11: ='Credit factor'!$E$4 -> 5e-07 | G11: 8.02491 | H11: 3.69291 | K11: =MAX(G11:J11) -> 8.02491 | L11: =+K11^2*E11 -> 3.219959e-05
A12: 4 | B12: 12.726343 | C12: 621.12124 | D12: ='Credit factor'!$D$2 -> Catastrophic failure | E12: ='Credit factor'!$E$2 -> 5e-07 | G12: 10.6524 | I12: 45.121 | J12: 30.01 | K12: =MAX(G12:J12) -> 45.121 | L12: =+K12^2*E12 -> 0.0010179523 | M12: =+SUM(L12:L14) -> 0.064285474
D13: ='Credit factor'!$D$3 -> 10 mm leak | E13: ='Credit factor'!$E$3 -> 1e-05 | G13: 62.8515 | H13: 35.9855 | I13: 45.121 | J13: 79.5211 | K13: =MAX(G13:J13) -> 79.5211 | L13: =+K13^2*E13 -> 0.063236053
D14: ='Credit factor'!$D$4 -> Continuous 10 min | E14: ='Credit factor'!$E$4 -> 5e-07 | G14: 7.93324 | H14: 3.65905 | K14: =MAX(G14:J14) -> 7.93324 | L14: =+K14^2*E14 -> 3.1468148e-05
A15: 5 | B15: 12.426343 | C15: 596.56534 | D15: ='Credit factor'!$D$2 -> Catastrophic failure | E15: ='Credit factor'!$E$2 -> 5e-07 | G15: 10.5659 | I15: 44.8006 | J15: 29.3981 | K15: =MAX(G15:J15) -> 44.8006 | L15: =+K15^2*E15 -> 0.0010035469 | M15: =+SUM(L15:L17) -> 0.063820315
D16: ='Credit factor'!$D$3 -> 10 mm leak | E16: ='Credit factor'!$E$3 -> 1e-05 | G16: 62.1421 | H16: 35.4513 | I16: 44.8006 | J16: 79.2376 | K16: =MAX(G16:J16) -> 79.2376 | L16: =+K16^2*E16 -> 0.062785973
D17: ='Credit factor'!$D$4 -> Continuous 10 min | E17: ='Credit factor'!$E$4 -> 5e-07 | G17: 7.84802 | H17: 3.62445 | K17: =MAX(G17:J17) -> 7.84802 | L17: =+K17^2*E17 -> 3.0795709e-05
A18: 6 | B18: 12.126343 | C18: 572.85882 | D18: ='Credit factor'!$D$2 -> Catastrophic failure | E18: ='Credit factor'!$E$2 -> 5e-07 | G18: 10.4776 | I18: 44.443 | J18: 28.6114 | K18: =MAX(G18:J18) -> 44.443 | L18: =+K18^2*E18 -> 0.00098759012 | M18: =+SUM(L18:L20) -> 0.063345563
D19: ='Credit factor'!$D$3 -> 10 mm leak | E19: ='Credit factor'!$E$3 -> 1e-05 | G19: 61.4093 | H19: 34.9195 | I19: 44.443 | J19: 78.948 | K19: =MAX(G19:J19) -> 78.948 | L19: =+K19^2*E19 -> 0.062327867
D20: ='Credit factor'!$D$4 -> Continuous 10 min | E20: ='Credit factor'!$E$4 -> 5e-07 | G20: 7.75962 | H20: 3.58909 | K20: =MAX(G20:J20) -> 7.75962 | L20: =+K20^2*E20 -> 3.0105851e-05
A21: 7 | B21: 11.826343 | C21: 549.95635 | D21: ='Credit factor'!$D$2 -> Catastrophic failure | E21: ='Credit factor'!$E$2 -> 5e-07 | G21: 10.3878 | I21: 44.0949 | J21: 27.7284 | K21: =MAX(G21:J21) -> 44.0949 | L21: =+K21^2*E21 -> 0.0009721801 | M21: =+SUM(L21:L23) -> 0.062862344
D22: ='Credit factor'!$D$3 -> 10 mm leak | E22: ='Credit factor'!$E$3 -> 1e-05 | G22: 60.6568 | H22: 34.3897 | I22: 44.0949 | J22: 78.6516 | K22: =MAX(G22:J22) -> 78.6516 | L22: =+K22^2*E22 -> 0.061860742
D23: ='Credit factor'!$D$4 -> Continuous 10 min | E23: ='Credit factor'!$E$4 -> 5e-07 | G23: 7.67099 | H23: 3.55296 | K23: =MAX(G23:J23) -> 7.67099 | L23: =+K23^2*E23 -> 2.9422044e-05
A24: 8 | B24: 11.526343 | C24: 527.81549 | D24: ='Credit factor'!$D$2 -> Catastrophic failure | E24: ='Credit factor'!$E$2 -> 5e-07 | G24: 10.2961 | I24: 43.733 | J24: 24.5865 | K24: =MAX(G24:J24) -> 43.733 | L24: =+K24^2*E24 -> 0.00095628764 | M24: =+SUM(L24:L26) -> 0.062371612
D25: ='Credit factor'!$D$3 -> 10 mm leak | E25: ='Credit factor'!$E$3 -> 1e-05 | G25: 60.0025 | H25: 33.8617 | I25: 43.733 | J25: 78.3496 | K25: =MAX(G25:J25) -> 78.3496 | L25: =+K25^2*E25 -> 0.061386598
D26: ='Credit factor'!$D$4 -> Continuous 10 min | E26: ='Credit factor'!$E$4 -> 5e-07 | G26: 7.57967 | H26: 3.51605 | K26: =MAX(G26:J26) -> 7.57967 | L26: =+K26^2*E26 -> 2.8725699e-05
A27: 9 | B27: 11.226343 | C27: 506.39654 | D27: ='Credit factor'!$D$2 -> Catastrophic failure | E27: ='Credit factor'!$E$2 -> 5e-07 | G27: 10.2029 | I27: 43.3381 | J27: 21.4275 | K27: =MAX(G27:J27) -> 43.3381 | L27: =+K27^2*E27 -> 0.00093909546 | M27: =+SUM(L27:L29) -> 0.061411671
D28: ='Credit factor'!$D$3 -> 10 mm leak | E28: ='Credit factor'!$E$3 -> 1e-05 | G28: 59.2703 | H28: 33.3349 | I28: 43.3381 | J28: 77.7461 | K28: =MAX(G28:J28) -> 77.7461 | L28: =+K28^2*E28 -> 0.060444561
D29: ='Credit factor'!$D$4 -> Continuous 10 min | E29: ='Credit factor'!$E$4 -> 5e-07 | G29: 7.48535 | H29: 3.47833 | K29: =MAX(G29:J29) -> 7.48535 | L29: =+K29^2*E29 -> 2.8015232e-05
A30: 10 | B30: 10.926343 | C30: 485.66227 | D30: ='Credit factor'!$D$2 -> Catastrophic failure | E30: ='Credit factor'!$E$2 -> 5e-07 | G30: 10.1086 | I30: 42.9886 | K30: =MAX(G30:J30) -> 42.9886 | L30: =+K30^2*E30 -> 0.00092400986 | M30: =+SUM(L30:L32) -> 0.060094039
D31: ='Credit factor'!$D$3 -> 10 mm leak | E31: ='Credit factor'!$E$3 -> 1e-05 | G31: 58.5046 | H31: 32.809 | I31: 42.9886 | J31: 76.9043 | K31: =MAX(G31:J31) -> 76.9043 | L31: =+K31^2*E31 -> 0.059142714
D32: ='Credit factor'!$D$4 -> Continuous 10 min | E32: ='Credit factor'!$E$4 -> 5e-07 | G32: 7.39133 | H32: 3.43978 | K32: =MAX(G32:J32) -> 7.39133 | L32: =+K32^2*E32 -> 2.731588e-05
A33: 11 | B33: 10.626343 | C33: 465.57776 | D33: ='Credit factor'!$D$2 -> Catastrophic failure | E33: ='Credit factor'!$E$2 -> 5e-07 | G33: 10.0133 | I33: 42.6205 | K33: =MAX(G33:J33) -> 42.6205 | L33: =+K33^2*E33 -> 0.00090825351 | M33: =+SUM(L33:L35) -> 0.058611732
D34: ='Credit factor'!$D$3 -> 10 mm leak | E34: ='Credit factor'!$E$3 -> 1e-05 | G34: 57.7195 | H34: 32.2837 | I34: 42.6205 | J34: 75.9453 | K34: =MAX(G34:J34) -> 75.9453 | L34: =+K34^2*E34 -> 0.057676886
D35: ='Credit factor'!$D$4 -> Continuous 10 min | E35: ='Credit factor'!$E$4 -> 5e-07 | G35: 7.2928 | H35: 3.40039 | K35: =MAX(G35:J35) -> 7.2928 | L35: =+K35^2*E35 -> 2.6592466e-05
A36: 12 | B36: 10.326343 | C36: 446.1102 | D36: ='Credit factor'!$D$2 -> Catastrophic failure | E36: ='Credit factor'!$E$2 -> 5e-07 | G36: 9.91414 | I36: 42.2236 | K36: =MAX(G36:J36) -> 42.2236 | L36: =+K36^2*E36 -> 0.0008914162 | M36: =+SUM(L36:L38) -> 0.057102397
D37: ='Credit factor'!$D$3 -> 10 mm leak | E37: ='Credit factor'!$E$3 -> 1e-05 | G37: 56.9679 | H37: 31.7585 | I37: 42.2236 | J37: 74.9567 | K37: =MAX(G37:J37) -> 74.9567 | L37: =+K37^2*E37 -> 0.056185069
D38: ='Credit factor'!$D$4 -> Continuous 10 min | E38: ='Credit factor'!$E$4 -> 5e-07 | G38: 7.19889 | H38: 3.36014 | K38: =MAX(G38:J38) -> 7.19889 | L38: =+K38^2*E38 -> 2.5912009e-05
A39: 13 | B39: 10.026343 | C39: 427.22875 | D39: ='Credit factor'!$D$2 -> Catastrophic failure | E39: ='Credit factor'!$E$2 -> 5e-07 | G39: 9.81638 | I39: 41.8344 | K39: =MAX(G39:J39) -> 41.8344 | L39: =+K39^2*E39 -> 0.00087505851 | M39: =+SUM(L39:L41) -> 0.055347979
D40: ='Credit factor'!$D$3 -> 10 mm leak | E40: ='Credit factor'!$E$3 -> 1e-05 | G40: 56.2258 | H40: 31.233 | I40: 41.8344 | J40: 73.7887 | K40: =MAX(G40:J40) -> 73.7887 | L40: =+K40^2*E40 -> 0.054447722
...

Sheet plot
A1: mass [kg] | B1: SOC [%] | C1: UHI [m2/yr] | Q1: mass [kg] | R1: SOC [%] | S1: UHI [m2/yr]
A2: {=IFERROR(INDEX(Results_Tank1!$B$3:$B$68, SMALL(IF(Results_Tank1!$B$3:$B$68<>"",ROW(Results_Tank1!$B$3:$B$68)-ROW(Results_Tank1!$B$3)+1),ROW(A2))),"")} -> 4.0641163 | B2: =A2/$C$24 -> 0.8647056 | C2: {=IFERROR(INDEX(Results_Tank1!$M$3:$M$68, SMALL(IF(Results_Tank1!$M$3:$M$68<>"",ROW(Results_Tank1!$M$3:$M$68)-ROW(Results_Tank1!$M$3)+1),ROW(C2))),"")} -> 0.029985624 | Q2: {=IFERROR(INDEX(Results_Tank2!$B$3:$B$140, SMALL(IF(Results_Tank2!$B$3:$B$140<>"",ROW(Results_Tank2!$B$3:$B$140)-ROW(Results_Tank2!$B$3)+1),ROW(Q2))),"")} -> 13.326343 | R2: =Q2/$S$48 -> 0.83289644 | S2: {=IFERROR(INDEX(Results_Tank2!$M$3:$M$140, SMALL(IF(Results_Tank2!$M$3:$M$140<>"",ROW(Results_Tank2!$M$3:$M$140)-ROW(Results_Tank2!$M$3)+1),ROW(S2))),"")} -> 0.065153902
A3: {=IFERROR(INDEX(Results_Tank1!$B$3:$B$68, SMALL(IF(Results_Tank1!$B$3:$B$68<>"",ROW(Results_Tank1!$B$3:$B$68)-ROW(Results_Tank1!$B$3)+1),ROW(A3))),"")} -> 3.8641163 | B3: =A3/$C$24 -> 0.82215241 | C3: {=IFERROR(INDEX(Results_Tank1!$M$3:$M$68, SMALL(IF(Results_Tank1!$M$3:$M$68<>"",ROW(Results_Tank1!$M$3:$M$68)-ROW(Results_Tank1!$M$3)+1),ROW(C3))),"")} -> 0.029626523 | Q3: {=IFERROR(INDEX(Results_Tank2!$B$3:$B$140, SMALL(IF(Results_Tank2!$B$3:$B$140<>"",ROW(Results_Tank2!$B$3:$B$140)-ROW(Results_Tank2!$B$3)+1),ROW(Q3))),"")} -> 13.026343 | R3: =Q3/$S$48 -> 0.81414644 | S3: {=IFERROR(INDEX(Results_Tank2!$M$3:$M$140, SMALL(IF(Results_Tank2!$M$3:$M$140<>"",ROW(Results_Tank2!$M$3:$M$140)-ROW(Results_Tank2!$M$3)+1),ROW(S3))),"")} -> 0.064718062
A4: {=IFERROR(INDEX(Results_Tank1!$B$3:$B$68, SMALL(IF(Results_Tank1!$B$3:$B$68<>"",ROW(Results_Tank1!$B$3:$B$68)-ROW(Results_Tank1!$B$3)+1),ROW(A4))),"")} -> 3.6641163 | B4: =A4/$C$24 -> 0.77959921 | C4: {=IFERROR(INDEX(Results_Tank1!$M$3:$M$68, SMALL(IF(Results_Tank1!$M$3:$M$68<>"",ROW(Results_Tank1!$M$3:$M$68)-ROW(Results_Tank1!$M$3)+1),ROW(C4))),"")} -> 0.029249193 | Q4: {=IFERROR(INDEX(Results_Tank2!$B$3:$B$140, SMALL(IF(Results_Tank2!$B$3:$B$140<>"",ROW(Results_Tank2!$B$3:$B$140)-ROW(Results_Tank2!$B$3)+1),ROW(Q4))),"")} -> 12.726343 | R4: =Q4/$S$48 -> 0.79539644 | S4: {=IFERROR(INDEX(Results_Tank2!$M$3:$M$140, SMALL(IF(Results_Tank2!$M$3:$M$140<>"",ROW(Results_Tank2!$M$3:$M$140)-ROW(Results_Tank2!$M$3)+1),ROW(S4))),"")} -> 0.064285474
A5: {=IFERROR(INDEX(Results_Tank1!$B$3:$B$68, SMALL(IF(Results_Tank1!$B$3:$B$68<>"",ROW(Results_Tank1!$B$3:$B$68)-ROW(Results_Tank1!$B$3)+1),ROW(A5))),"")} -> 3.4641163 | B5: =A5/$C$24 -> 0.73704602 | C5: {=IFERROR(INDEX(Results_Tank1!$M$3:$M$68, SMALL(IF(Results_Tank1!$M$3:$M$68<>"",ROW(Results_Tank1!$M$3:$M$68)-ROW(Results_Tank1!$M$3)+1),ROW(C5))),"")} -> 0.028467784 | Q5: {=IFERROR(INDEX(Results_Tank2!$B$3:$B$140, SMALL(IF(Results_Tank2!$B$3:$B$140<>"",ROW(Results_Tank2!$B$3:$B$140)-ROW(Results_Tank2!$B$3)+1),ROW(Q5))),"")} -> 12.426343 | R5: =Q5/$S$48 -> 0.77664644 | S5: {=IFERROR(INDEX(Results_Tank2!$M$3:$M$140, SMALL(IF(Results_Tank2!$M$3:$M$140<>"",ROW(Results_Tank2!$M$3:$M$140)-ROW(Results_Tank2!$M$3)+1),ROW(S5))),"")} -> 0.063820315
A6: {=IFERROR(INDEX(Results_Tank1!$B$3:$B$68, SMALL(IF(Results_Tank1!$B$3:$B$68<>"",ROW(Results_Tank1!$B$3:$B$68)-ROW(Results_Tank1!$B$3)+1),ROW(A6))),"")} -> 3.2641163 | B6: =A6/$C$24 -> 0.69449283 | C6: {=IFERROR(INDEX(Results_Tank1!$M$3:$M$68, SMALL(IF(Results_Tank1!$M$3:$M$68<>"",ROW(Results_Tank1!$M$3:$M$68)-ROW(Results_Tank1!$M$3)+1),ROW(C6))),"")} -> 0.027504235 | Q6: {=IFERROR(INDEX(Results_Tank2!$B$3:$B$140, SMALL(IF(Results_Tank2!$B$3:$B$140<>"",ROW(Results_Tank2!$B$3:$B$140)-ROW(Results_Tank2!$B$3)+1),ROW(Q6))),"")} -> 12.126343 | R6: =Q6/$S$48 -> 0.75789644 | S6: {=IFERROR(INDEX(Results_Tank2!$M$3:$M$140, SMALL(IF(Results_Tank2!$M$3:$M$140<>"",ROW(Results_Tank2!$M$3:$M$140)-ROW(Results_Tank2!$M$3)+1),ROW(S6))),"")} -> 0.063345563
A7: {=IFERROR(INDEX(Results_Tank1!$B$3:$B$68, SMALL(IF(Results_Tank1!$B$3:$B$68<>"",ROW(Results_Tank1!$B$3:$B$68)-ROW(Results_Tank1!$B$3)+1),ROW(A7))),"")} -> 3.0641163 | B7: =A7/$C$24 -> 0.65193964 | C7: {=IFERROR(INDEX(Results_Tank1!$M$3:$M$68, SMALL(IF(Results_Tank1!$M$3:$M$68<>"",ROW(Results_Tank1!$M$3:$M$68)-ROW(Results_Tank1!$M$3)+1),ROW(C7))),"")} -> 0.026431327 | Q7: {=IFERROR(INDEX(Results_Tank2!$B$3:$B$140, SMALL(IF(Results_Tank2!$B$3:$B$140<>"",ROW(Results_Tank2!$B$3:$B$140)-ROW(Results_Tank2!$B$3)+1),ROW(Q7))),"")} -> 11.826343 | R7: =Q7/$S$48 -> 0.73914644 | S7: {=IFERROR(INDEX(Results_Tank2!$M$3:$M$140, SMALL(IF(Results_Tank2!$M$3:$M$140<>"",ROW(Results_Tank2!$M$3:$M$140)-ROW(Results_Tank2!$M$3)+1),ROW(S7))),"")} -> 0.062862344
A8: {=IFERROR(INDEX(Results_Tank1!$B$3:$B$68, SMALL(IF(Results_Tank1!$B$3:$B$68<>"",ROW(Results_Tank1!$B$3:$B$68)-ROW(Results_Tank1!$B$3)+1),ROW(A8))),"")} -> 2.8641163 | B8: =A8/$C$24 -> 0.60938645 | C8: {=IFERROR(INDEX(Results_Tank1!$M$3:$M$68, SMALL(IF(Results_Tank1!$M$3:$M$68<>"",ROW(Results_Tank1!$M$3:$M$68)-ROW(Results_Tank1!$M$3)+1),ROW(C8))),"")} -> 0.025183954 | Q8: {=IFERROR(INDEX(Results_Tank2!$B$3:$B$140, SMALL(IF(Results_Tank2!$B$3:$B$140<>"",ROW(Results_Tank2!$B$3:$B$140)-ROW(Results_Tank2!$B$3)+1),ROW(Q8))),"")} -> 11.526343 | R8: =Q8/$S$48 -> 0.72039644 | S8: {=IFERROR(INDEX(Results_Tank2!$M$3:$M$140, SMALL(IF(Results_Tank2!$M$3:$M$140<>"",ROW(Results_Tank2!$M$3:$M$140)-ROW(Results_Tank2!$M$3)+1),ROW(S8))),"")} -> 0.062371612
A9: {=IFERROR(INDEX(Results_Tank1!$B$3:$B$68, SMALL(IF(Results_Tank1!$B$3:$B$68<>"",ROW(Results_Tank1!$B$3:$B$68)-ROW(Results_Tank1!$B$3)+1),ROW(A9))),"")} -> 2.6641163 | B9: =A9/$C$24 -> 0.56683326 | C9: {=IFERROR(INDEX(Results_Tank1!$M$3:$M$68, SMALL(IF(Results_Tank1!$M$3:$M$68<>"",ROW(Results_Tank1!$M$3:$M$68)-ROW(Results_Tank1!$M$3)+1),ROW(C9))),"")} -> 0.017112994 | Q9: {=IFERROR(INDEX(Results_Tank2!$B$3:$B$140, SMALL(IF(Results_Tank2!$B$3:$B$140<>"",ROW(Results_Tank2!$B$3:$B$140)-ROW(Results_Tank2!$B$3)+1),ROW(Q9))),"")} -> 11.226343 | R9: =Q9/$S$48 -> 0.70164644 | S9: {=IFERROR(INDEX(Results_Tank2!$M$3:$M$140, SMALL(IF(Results_Tank2!$M$3:$M$140<>"",ROW(Results_Tank2!$M$3:$M$140)-ROW(Results_Tank2!$M$3)+1),ROW(S9))),"")} -> 0.061411671
A10: {=IFERROR(INDEX(Results_Tank1!$B$3:$B$68, SMALL(IF(Results_Tank1!$B$3:$B$68<>"",ROW(Results_Tank1!$B$3:$B$68)-ROW(Results_Tank1!$B$3)+1),ROW(A10))),"")} -> 2.4641163 | B10: =A10/$C$24 -> 0.52428007 | C10: {=IFERROR(INDEX(Results_Tank1!$M$3:$M$68, SMALL(IF(Results_Tank1!$M$3:$M$68<>"",ROW(Results_Tank1!$M$3:$M$68)-ROW(Results_Tank1!$M$3)+1),ROW(C10))),"")} -> 0.016868423 | Q10: {=IFERROR(INDEX(Results_Tank2!$B$3:$B$140, SMALL(IF(Results_Tank2!$B$3:$B$140<>"",ROW(Results_Tank2!$B$3:$B$140)-ROW(Results_Tank2!$B$3)+1),ROW(Q10))),"")} -> 10.926343 | R10: =Q10/$S$48 -> 0.68289644 | S10: {=IFERROR(INDEX(Results_Tank2!$M$3:$M$140, SMALL(IF(Results_Tank2!$M$3:$M$140<>"",ROW(Results_Tank2!$M$3:$M$140)-ROW(Results_Tank2!$M$3)+1),ROW(S10))),"")} -> 0.060094039
A11: {=IFERROR(INDEX(Results_Tank1!$B$3:$B$68, SMALL(IF(Results_Tank1!$B$3:$B$68<>"",ROW(Results_Tank1!$B$3:$B$68)-ROW(Results_Tank1!$B$3)+1),ROW(A11))),"")} -> 2.2641163 | B11: =A11/$C$24 -> 0.48172687 | C11: {=IFERROR(INDEX(Results_Tank1!$M$3:$M$68, SMALL(IF(Results_Tank1!$M$3:$M$68<>"",ROW(Results_Tank1!$M$3:$M$68)-ROW(Results_Tank1!$M$3)+1),ROW(C11))),"")} -> 0.016529319 | Q11: {=IFERROR(INDEX(Results_Tank2!$B$3:$B$140, SMALL(IF(Results_Tank2!$B$3:$B$140<>"",ROW(Results_Tank2!$B$3:$B$140)-ROW(Results_Tank2!$B$3)+1),ROW(Q11))),"")} -> 10.626343 | R11: =Q11/$S$48 -> 0.66414644 | S11: {=IFERROR(INDEX(Results_Tank2!$M$3:$M$140, SMALL(IF(Results_Tank2!$M$3:$M$140<>"",ROW(Results_Tank2!$M$3:$M$140)-ROW(Results_Tank2!$M$3)+1),ROW(S11))),"")} -> 0.058611732
A12: {=IFERROR(INDEX(Results_Tank1!$B$3:$B$68, SMALL(IF(Results_Tank1!$B$3:$B$68<>"",ROW(Results_Tank1!$B$3:$B$68)-ROW(Results_Tank1!$B$3)+1),ROW(A12))),"")} -> 2.0641163 | B12: =A12/$C$24 -> 0.43917368 | C12: {=IFERROR(INDEX(Results_Tank1!$M$3:$M$68, SMALL(IF(Results_Tank1!$M$3:$M$68<>"",ROW(Results_Tank1!$M$3:$M$68)-ROW(Results_Tank1!$M$3)+1),ROW(C12))),"")} -> 0.016150439 | Q12: {=IFERROR(INDEX(Results_Tank2!$B$3:$B$140, SMALL(IF(Results_Tank2!$B$3:$B$140<>"",ROW(Results_Tank2!$B$3:$B$140)-ROW(Results_Tank2!$B$3)+1),ROW(Q12))),"")} -> 10.326343 | R12: =Q12/$S$48 -> 0.64539644 | S12: {=IFERROR(INDEX(Results_Tank2!$M$3:$M$140, SMALL(IF(Results_Tank2!$M$3:$M$140<>"",ROW(Results_Tank2!$M$3:$M$140)-ROW(Results_Tank2!$M$3)+1),ROW(S12))),"")} -> 0.057102397
A13: {=IFERROR(INDEX(Results_Tank1!$B$3:$B$68, SMALL(IF(Results_Tank1!$B$3:$B$68<>"",ROW(Results_Tank1!$B$3:$B$68)-ROW(Results_Tank1!$B$3)+1),ROW(A13))),"")} -> 1.8641163 | B13: =A13/$C$24 -> 0.39662049 | C13: {=IFERROR(INDEX(Results_Tank1!$M$3:$M$68, SMALL(IF(Results_Tank1!$M$3:$M$68<>"",ROW(Results_Tank1!$M$3:$M$68)-ROW(Results_Tank1!$M$3)+1),ROW(C13))),"")} -> 0.015718523 | Q13: {=IFERROR(INDEX(Results_Tank2!$B$3:$B$140, SMALL(IF(Results_Tank2!$B$3:$B$140<>"",ROW(Results_Tank2!$B$3:$B$140)-ROW(Results_Tank2!$B$3)+1),ROW(Q13))),"")} -> 10.026343 | R13: =Q13/$S$48 -> 0.62664644 | S13: {=IFERROR(INDEX(Results_Tank2!$M$3:$M$140, SMALL(IF(Results_Tank2!$M$3:$M$140<>"",ROW(Results_Tank2!$M$3:$M$140)-ROW(Results_Tank2!$M$3)+1),ROW(S13))),"")} -> 0.055347979
... A22: {=IFERROR(INDEX(Results_Tank1!$B$3:$B$68, SMALL(IF(Results_Tank1!$B$3:$B$68<>"",ROW(Results_Tank1!$B$3:$B$68)-ROW(Results_Tank1!$B$3)+1),ROW(A22))),"")} -> 0.064116308 | B22: =A22/$C$24 -> 0.013641768 | C22: {=IFERROR(INDEX(Results_Tank1!$M$3:$M$68, SMALL(IF(Results_Tank1!$M$3:$M$68<>"",ROW(Results_Tank1!$M$3:$M$68)-ROW(Results_Tank1!$M$3)+1),ROW(C22))),"")} -> 0 | Q22: {=IFERROR(INDEX(Results_Tank2!$B$3:$B$140, SMALL(IF(Results_Tank2!$B$3:$B$140<>"",ROW(Results_Tank2!$B$3:$B$140)-ROW(Results_Tank2!$B$3)+1),ROW(Q22))),"")} -> 7.3263431 | R22: =Q22/$S$48 -> 0.45789644 | S22: {=IFERROR(INDEX(Results_Tank2!$M$3:$M$140, SMALL(IF(Results_Tank2!$M$3:$M$140<>"",ROW(Results_Tank2!$M$3:$M$140)-ROW(Results_Tank2!$M$3)+1),ROW(S22))),"")} -> 0.041383334
A23: {=IFERROR(INDEX(Results_Tank1!$B$3:$B$68, SMALL(IF(Results_Tank1!$B$3:$B$68<>"",ROW(Results_Tank1!$B$3:$B$68)-ROW(Results_Tank1!$B$3)+1),ROW(A23))),"")} | Q23: {=IFERROR(INDEX(Results_Tank2!$B$3:$B$140, SMALL(IF(Results_Tank2!$B$3:$B$140<>"",ROW(Results_Tank2!$B$3:$B$140)-ROW(Results_Tank2!$B$3)+1),ROW(Q23))),"")} -> 7.0263431 | R23: =Q23/$S$48 -> 0.43914644 | S23: {=IFERROR(INDEX(Results_Tank2!$M$3:$M$140, SMALL(IF(Results_Tank2!$M$3:$M$140<>"",ROW(Results_Tank2!$M$3:$M$140)-ROW(Results_Tank2!$M$3)+1),ROW(S23))),"")} -> 0.040654397
A24: mass | C24: 4.7 | D24: kg | Q24: {=IFERROR(INDEX(Results_Tank2!$B$3:$B$140, SMALL(IF(Results_Tank2!$B$3:$B$140<>"",ROW(Results_Tank2!$B$3:$B$140)-ROW(Results_Tank2!$B$3)+1),ROW(Q24))),"")} -> 6.7263431 | R24: =Q24/$S$48 -> 0.42039644 | S24: {=IFERROR(INDEX(Results_Tank2!$M$3:$M$140, SMALL(IF(Results_Tank2!$M$3:$M$140<>"",ROW(Results_Tank2!$M$3:$M$140)-ROW(Results_Tank2!$M$3)+1),ROW(S24))),"")} -> 0.038640901
A25: max | C25: =C24*0.9 -> 4.23 | D25: kg | Q25: {=IFERROR(INDEX(Results_Tank2!$B$3:$B$140, SMALL(IF(Results_Tank2!$B$3:$B$140<>"",ROW(Results_Tank2!$B$3:$B$140)-ROW(Results_Tank2!$B$3)+1),ROW(Q25))),"")} -> 6.4263431 | R25: =Q25/$S$48 -> 0.40164644 | S25: {=IFERROR(INDEX(Results_Tank2!$M$3:$M$140, SMALL(IF(Results_Tank2!$M$3:$M$140<>"",ROW(Results_Tank2!$M$3:$M$140)-ROW(Results_Tank2!$M$3)+1),ROW(S25))),"")} -> 0.036013347
A26: min | C26: =C24*0.1 -> 0.47 | D26: kg | Q26: {=IFERROR(INDEX(Results_Tank2!$B$3:$B$140, SMALL(IF(Results_Tank2!$B$3:$B$140<>"",ROW(Results_Tank2!$B$3:$B$140)-ROW(Results_Tank2!$B$3)+1),ROW(Q26))),"")} -> 6.1263431 | R26: =Q26/$S$48 -> 0.38289644 | S26: {=IFERROR(INDEX(Results_Tank2!$M$3:$M$140, SMALL(IF(Results_Tank2!$M$3:$M$140<>"",ROW(Results_Tank2!$M$3:$M$140)-ROW(Results_Tank2!$M$3)+1),ROW(S26))),"")} -> 0.027923917
A27: {=IFERROR(INDEX(Results_Tank1!$B$3:$B$68, SMALL(IF(Results_Tank1!$B$3:$B$68<>"",ROW(Results_Tank1!$B$3:$B$68)-ROW(Results_Tank1!$B$3)+1),ROW(A27))),"")} | Q27: {=IFERROR(INDEX(Results_Tank2!$B$3:$B$140, SMALL(IF(Results_Tank2!$B$3:$B$140<>"",ROW(Results_Tank2!$B$3:$B$140)-ROW(Results_Tank2!$B$3)+1),ROW(Q27))),"")} -> 5.8263431 | R27: =Q27/$S$48 -> 0.36414644 | S27: {=IFERROR(INDEX(Results_Tank2!$M$3:$M$140, SMALL(IF(Results_Tank2!$M$3:$M$140<>"",ROW(Results_Tank2!$M$3:$M$140)-ROW(Results_Tank2!$M$3)+1),ROW(S27))),"")} -> 0.027529563
A28: {=IFERROR(INDEX(Results_Tank1!$B$3:$B$68, SMALL(IF(Results_Tank1!$B$3:$B$68<>"",ROW(Results_Tank1!$B$3:$B$68)-ROW(Results_Tank1!$B$3)+1),ROW(A28))),"")} | Q28: {=IFERROR(INDEX(Results_Tank2!$B$3:$B$140, SMALL(IF(Results_Tank2!$B$3:$B$140<>"",ROW(Results_Tank2!$B$3:$B$140)-ROW(Results_Tank2!$B$3)+1),ROW(Q28))),"")} -> 5.5263431 | R28: =Q28/$S$48 -> 0.34539644 | S28: {=IFERROR(INDEX(Results_Tank2!$M$3:$M$140, SMALL(IF(Results_Tank2!$M$3:$M$140<>"",ROW(Results_Tank2!$M$3:$M$140)-ROW(Results_Tank2!$M$3)+1),ROW(S28))),"")} -> 0.027117559
A29: {=IFERROR(INDEX(Results_Tank1!$B$3:$B$68, SMALL(IF(Results_Tank1!$B$3:$B$68<>"",ROW(Results_Tank1!$B$3:$B$68)-ROW(Results_Tank1!$B$3)+1),ROW(A29))),"")} | Q29: {=IFERROR(INDEX(Results_Tank2!$B$3:$B$140, SMALL(IF(Results_Tank2!$B$3:$B$140<>"",ROW(Results_Tank2!$B$3:$B$140)-ROW(Results_Tank2!$B$3)+1),ROW(Q29))),"")} -> 5.2263431 | R29: =Q29/$S$48 -> 0.32664644 | S29: {=IFERROR(INDEX(Results_Tank2!$M$3:$M$140, SMALL(IF(Results_Tank2!$M$3:$M$140<>"",ROW(Results_Tank2!$M$3:$M$140)-ROW(Results_Tank2!$M$3)+1),ROW(S29))),"")} -> 0.026691205
A30: {=IFERROR(INDEX(Results_Tank1!$B$3:$B$68, SMALL(IF(Results_Tank1!$B$3:$B$68<>"",ROW(Results_Tank1!$B$3:$B$68)-ROW(Results_Tank1!$B$3)+1),ROW(A30))),"")} | Q30: {=IFERROR(INDEX(Results_Tank2!$B$3:$B$140, SMALL(IF(Results_Tank2!$B$3:$B$140<>"",ROW(Results_Tank2!$B$3:$B$140)-ROW(Results_Tank2!$B$3)+1),ROW(Q30))),"")} -> 4.9263431 | R30: =Q30/$S$48 -> 0.30789644 | S30: {=IFERROR(INDEX(Results_Tank2!$M$3:$M$140, SMALL(IF(Results_Tank2!$M$3:$M$140<>"",ROW(Results_Tank2!$M$3:$M$140)-ROW(Results_Tank2!$M$3)+1),ROW(S30))),"")} -> 0.026241698
A31: {=IFERROR(INDEX(Results_Tank1!$B$3:$B$68, SMALL(IF(Results_Tank1!$B$3:$B$68<>"",ROW(Results_Tank1!$B$3:$B$68)-ROW(Results_Tank1!$B$3)+1),ROW(A31))),"")} | Q31: {=IFERROR(INDEX(Results_Tank2!$B$3:$B$140, SMALL(IF(Results_Tank2!$B$3:$B$140<>"",ROW(Results_Tank2!$B$3:$B$140)-ROW(Results_Tank2!$B$3)+1),ROW(Q31))),"")} -> 4.6263431 | R31: =Q31/$S$48 -> 0.28914644 | S31: {=IFERROR(INDEX(Results_Tank2!$M$3:$M$140, SMALL(IF(Results_Tank2!$M$3:$M$140<>"",ROW(Results_Tank2!$M$3:$M$140)-ROW(Results_Tank2!$M$3)+1),ROW(S31))),"")} -> 0.025807259
A32: {=IFERROR(INDEX(Results_Tank1!$B$3:$B$68, SMALL(IF(Results_Tank1!$B$3:$B$68<>"",ROW(Results_Tank1!$B$3:$B$68)-ROW(Results_Tank1!$B$3)+1),ROW(A32))),"")} | Q32: {=IFERROR(INDEX(Results_Tank2!$B$3:$B$140, SMALL(IF(Results_Tank2!$B$3:$B$140<>"",ROW(Results_Tank2!$B$3:$B$140)-ROW(Results_Tank2!$B$3)+1),ROW(Q32))),"")} -> 4.3263431 | R32: =Q32/$S$48 -> 0.27039644 | S32: {=IFERROR(INDEX(Results_Tank2!$M$3:$M$140, SMALL(IF(Results_Tank2!$M$3:$M$140<>"",ROW(Results_Tank2!$M$3:$M$140)-ROW(Results_Tank2!$M$3)+1),ROW(S32))),"")} -> 0.025371124
A33: {=IFERROR(INDEX(Results_Tank1!$B$3:$B$68, SMALL(IF(Results_Tank1!$B$3:$B$68<>"",ROW(Results_Tank1!$B$3:$B$68)-ROW(Results_Tank1!$B$3)+1),ROW(A33))),"")} | Q33: {=IFERROR(INDEX(Results_Tank2!$B$3:$B$140, SMALL(IF(Results_Tank2!$B$3:$B$140<>"",ROW(Results_Tank2!$B$3:$B$140)-ROW(Results_Tank2!$B$3)+1),ROW(Q33))),"")} -> 4.0263431 | R33: =Q33/$S$48 -> 0.25164644 | S33: {=IFERROR(INDEX(Results_Tank2!$M$3:$M$140, SMALL(IF(Results_Tank2!$M$3:$M$140<>"",ROW(Results_Tank2!$M$3:$M$140)-ROW(Results_Tank2!$M$3)+1),ROW(S33))),"")} -> 0.02426113
A34: {=IFERROR(INDEX(Results_Tank1!$B$3:$B$68, SMALL(IF(Results_Tank1!$B$3:$B$68<>"",ROW(Results_Tank1!$B$3:$B$68)-ROW(Results_Tank1!$B$3)+1),ROW(A34))),"")} | Q34: {=IFERROR(INDEX(Results_Tank2!$B$3:$B$140, SMALL(IF(Results_Tank2!$B$3:$B$140<>"",ROW(Results_Tank2!$B$3:$B$140)-ROW(Results_Tank2!$B$3)+1),ROW(Q34))),"")} -> 3.7263431 | R34: =Q34/$S$48 -> 0.23289644 | S34: {=IFERROR(INDEX(Results_Tank2!$M$3:$M$140, SMALL(IF(Results_Tank2!$M$3:$M$140<>"",ROW(Results_Tank2!$M$3:$M$140)-ROW(Results_Tank2!$M$3)+1),ROW(S34))),"")} -> 0.015644362
A35: {=IFERROR(INDEX(Results_Tank1!$B$3:$B$68, SMALL(IF(Results_Tank1!$B$3:$B$68<>"",ROW(Results_Tank1!$B$3:$B$68)-ROW(Results_Tank1!$B$3)+1),ROW(A35))),"")} | Q35: {=IFERROR(INDEX(Results_Tank2!$B$3:$B$140, SMALL(IF(Results_Tank2!$B$3:$B$140<>"",ROW(Results_Tank2!$B$3:$B$140)-ROW(Results_Tank2!$B$3)+1),ROW(Q35))),"")} -> 3.4263431 | R35: =Q35/$S$48 -> 0.21414644 | S35: {=IFERROR(INDEX(Results_Tank2!$M$3:$M$140, SMALL(IF(Results_Tank2!$M$3:$M$140<>"",ROW(Results_Tank2!$M$3:$M$140)-ROW(Results_Tank2!$M$3)+1),ROW(S35))),"")} -> 0.01528159
A36: {=IFERROR(INDEX(Results_Tank1!$B$3:$B$68, SMALL(IF(Results_Tank1!$B$3:$B$68<>"",ROW(Results_Tank1!$B$3:$B$68)-ROW(Results_Tank1!$B$3)+1),ROW(A36))),"")} | Q36: {=IFERROR(INDEX(Results_Tank2!$B$3:$B$140, SMALL(IF(Results_Tank2!$B$3:$B$140<>"",ROW(Results_Tank2!$B$3:$B$140)-ROW(Results_Tank2!$B$3)+1),ROW(Q36))),"")} -> 3.1263431 | R36: =Q36/$S$48 -> 0.19539644 | S36: {=IFERROR(INDEX(Results_Tank2!$M$3:$M$140, SMALL(IF(Results_Tank2!$M$3:$M$140<>"",ROW(Results_Tank2!$M$3:$M$140)-ROW(Results_Tank2!$M$3)+1),ROW(S36))),"")} -> 0.014897389
A37: {=IFERROR(INDEX(Results_Tank1!$B$3:$B$68, SMALL(IF(Results_Tank1!$B$3:$B$68<>"",ROW(Results_Tank1!$B$3:$B$68)-ROW(Results_Tank1!$B$3)+1),ROW(A37))),"")} | Q37: {=IFERROR(INDEX(Results_Tank2!$B$3:$B$140, SMALL(IF(Results_Tank2!$B$3:$B$140<>"",ROW(Results_Tank2!$B$3:$B$140)-ROW(Results_Tank2!$B$3)+1),ROW(Q37))),"")} -> 2.8263431 | R37: =Q37/$S$48 -> 0.17664644 | S37: {=IFERROR(INDEX(Results_Tank2!$M$3:$M$140, SMALL(IF(Results_Tank2!$M$3:$M$140<>"",ROW(Results_Tank2!$M$3:$M$140)-ROW(Results_Tank2!$M$3)+1),ROW(S37))),"")} -> 0.014493488
A38: =IFERROR(INDEX(Results_Tank1!$B$3:$B$68,SMALL(IF(Results_Tank1!$B$3:$B$68<>"", ROW(Results_Tank1!$B$3:$B$68)-ROW(Results_Tank1!$B$3:$B$68)+1),ROW(A37))),"") | Q38: {=IFERROR(INDEX(Results_Tank2!$B$3:$B$140, SMALL(IF(Results_Tank2!$B$3:$B$140<>"",ROW(Results_Tank2!$B$3:$B$140)-ROW(Results_Tank2!$B$3)+1),ROW(Q38))),"")} -> 2.5263431 | R38: =Q38/$S$48 -> 0.15789644 | S38: {=IFERROR(INDEX(Results_Tank2!$M$3:$M$140, SMALL(IF(Results_Tank2!$M$3:$M$140<>"",ROW(Results_Tank2!$M$3:$M$140)-ROW(Results_Tank2!$M$3)+1),ROW(S38))),"")} -> 0.014085269
A39: =IFERROR(INDEX(Results_Tank1!$B$3:$B$68,SMALL(IF(Results_Tank1!$B$3:$B$68<>"", ROW(Results_Tank1!$B$3:$B$68)-ROW(Results_Tank1!$B$3:$B$68)+1),ROW(A38))),"") | Q39: {=IFERROR(INDEX(Results_Tank2!$B$3:$B$140, SMALL(IF(Results_Tank2!$B$3:$B$140<>"",ROW(Results_Tank2!$B$3:$B$140)-ROW(Results_Tank2!$B$3)+1),ROW(Q39))),"")} -> 2.2263431 | R39: =Q39/$S$48 -> 0.13914644 | S39: {=IFERROR(INDEX(Results_Tank2!$M$3:$M$140, SMALL(IF(Results_Tank2!$M$3:$M$140<>"",ROW(Results_Tank2!$M$3:$M$140)-ROW(Results_Tank2!$M$3)+1),ROW(S39))),"")} -> 0.013660639
Q40: {=IFERROR(INDEX(Results_Tank2!$B$3:$B$140, SMALL(IF(Results_Tank2!$B$3:$B$140<>"",ROW(Results_Tank2!$B$3:$B$140)-ROW(Results_Tank2!$B$3)+1),ROW(Q40))),"")} -> 1.9263431 | R40: =Q40/$S$48 -> 0.12039644 | S40: {=IFERROR(INDEX(Results_Tank2!$M$3:$M$140, SMALL(IF(Results_Tank2!$M$3:$M$140<>"",ROW(Results_Tank2!$M$3:$M$140)-ROW(Results_Tank2!$M$3)+1),ROW(S40))),"")} -> 0.007955138
Q41: {=IFERROR(INDEX(Results_Tank2!$B$3:$B$140, SMALL(IF(Results_Tank2!$B$3:$B$140<>"",ROW(Results_Tank2!$B$3:$B$140)-ROW(Results_Tank2!$B$3)+1),ROW(Q41))),"")} -> 1.6263431 | R41: =Q41/$S$48 -> 0.10164644 | S41: {=IFERROR(INDEX(Results_Tank2!$M$3:$M$140, SMALL(IF(Results_Tank2!$M$3:$M$140<>"",ROW(Results_Tank2!$M$3:$M$140)-ROW(Results_Tank2!$M$3)+1),ROW(S41))),"")} -> 0.0068386042
Q42: {=IFERROR(INDEX(Results_Tank2!$B$3:$B$140, SMALL(IF(Results_Tank2!$B$3:$B$140<>"",ROW(Results_Tank2!$B$3:$B$140)-ROW(Results_Tank2!$B$3)+1),ROW(Q42))),"")} -> 1.3263431 | R42: =Q42/$S$48 -> 0.082896441 | S42: {=IFERROR(INDEX(Results_Tank2!$M$3:$M$140, SMALL(IF(Results_Tank2!$M$3:$M$140<>"",ROW(Results_Tank2!$M$3:$M$140)-ROW(Results_Tank2!$M$3)+1),ROW(S42))),"")} -> 0.0063739367
Q43: {=IFERROR(INDEX(Results_Tank2!$B$3:$B$140, SMALL(IF(Results_Tank2!$B$3:$B$140<>"",ROW(Results_Tank2!$B$3:$B$140)-ROW(Results_Tank2!$B$3)+1),ROW(Q43))),"")} -> 1.0263431 | R43: =Q43/$S$48 -> 0.064146441 | S43: {=IFERROR(INDEX(Results_Tank2!$M$3:$M$140, SMALL(IF(Results_Tank2!$M$3:$M$140<>"",ROW(Results_Tank2!$M$3:$M$140)-ROW(Results_Tank2!$M$3)+1),ROW(S43))),"")} -> 0.0060209783
Q44: {=IFERROR(INDEX(Results_Tank2!$B$3:$B$140, SMALL(IF(Results_Tank2!$B$3:$B$140<>"",ROW(Results_Tank2!$B$3:$B$140)-ROW(Results_Tank2!$B$3)+1),ROW(Q44))),"")} -> 0.72634306 | R44: =Q44/$S$48 -> 0.045396441 | S44: {=IFERROR(INDEX(Results_Tank2!$M$3:$M$140, SMALL(IF(Results_Tank2!$M$3:$M$140<>"",ROW(Results_Tank2!$M$3:$M$140)-ROW(Results_Tank2!$M$3)+1),ROW(S44))),"")} -> 0.003434932
Q45: {=IFERROR(INDEX(Results_Tank2!$B$3:$B$140, SMALL(IF(Results_Tank2!$B$3:$B$140<>"",ROW(Results_Tank2!$B$3:$B$140)-ROW(Results_Tank2!$B$3)+1),ROW(Q45))),"")} -> 0.42634306 | R45: =Q45/$S$48 -> 0.026646441 | S45: {=IFERROR(INDEX(Results_Tank2!$M$3:$M$140, SMALL(IF(Results_Tank2!$M$3:$M$140<>"",ROW(Results_Tank2!$M$3:$M$140)-ROW(Results_Tank2!$M$3)+1),ROW(S45))),"")} -> 0.0023872548
Q46: {=IFERROR(INDEX(Results_Tank2!$B$3:$B$140, SMALL(IF(Results_Tank2!$B$3:$B$140<>"",ROW(Results_Tank2!$B$3:$B$140)-ROW(Results_Tank2!$B$3)+1),ROW(Q46))),"")} -> 0.12634306 | R46: =Q46/$S$48 -> 0.007896441 | S46: {=IFERROR(INDEX(Results_Tank2!$M$3:$M$140, SMALL(IF(Results_Tank2!$M$3:$M$140<>"",ROW(Results_Tank2!$M$3:$M$140)-ROW(Results_Tank2!$M$3)+1),ROW(S46))),"")} -> 0.00067946893
Q48: mass | S48: 16 | T48: kg
Q49: max | S49: =S48*0.9 -> 14.4 | T49: kg
...
